<?xml version="0.0" ?>

<robot name="redmax_hand">
    
    <link name="link0">
        <inertial>
            <origin rpy="0.00000 -0.00000 0.00000" xyz="0.00000 0.00000 0.00000"/>
            <mass value="0.000000001"/>
            <inertia ixx="0.0" ixy="0" ixz="0" iyy="0.0" iyz="0" izz="0.0"/>
        </inertial>
        <visual>
            <origin rpy="0 0 0.0" xyz="0 0 0"/>
            <geometry>
                <mesh filename="meshes/hand/body0.obj" scale="1 1 1"/>
            </geometry>
        </visual>
    </link>

    <link name="link1">
        <inertial>
            <origin rpy="0.00000 -0.00000 0.00000" xyz="0.00000 0.00000 0.00000"/>
            <mass value="0.000000001"/>
            <inertia ixx="0.0" ixy="0" ixz="0" iyy="0.0" iyz="0" izz="0.0"/>
        </inertial>
        <visual>
            <origin rpy="0 0 0.0" xyz="0 0 0"/>
            <geometry>
                <mesh filename="meshes/hand/body1.obj" scale="1 1 1"/>
            </geometry>
        </visual>
    </link>

    <joint name="link_0_1" type="revolute">
        <parent link="link0"/>
        <child link="link1"/>
        <origin xyz="-3.300000 -5.689700 0.000000"/>
        <axis xyz="0.000000 0.000000 -1.000000"/>
    </joint>

    <link name="link2">
        <inertial>
            <origin rpy="0.00000 -0.00000 0.00000" xyz="0.00000 0.00000 0.00000"/>
            <mass value="0.000000001"/>
            <inertia ixx="0.0" ixy="0" ixz="0" iyy="0.0" iyz="0" izz="0.0"/>
        </inertial>
        <visual>
            <origin rpy="0 0 0.0" xyz="0 0 0"/>
            <geometry>
                <mesh filename="meshes/hand/body2.obj" scale="1 1 1"/>
            </geometry>
        </visual>
    </link>

    <joint name="link_1_2" type="revolute">
        <parent link="link1"/>
        <child link="link2"/>
        <origin xyz="-3.300000 -7.680000 0.000000"/>
        <axis xyz="1.000000 0.000000 0.000000"/>
    </joint>

    <link name="link3">
        <inertial>
            <origin rpy="0.00000 -0.00000 0.00000" xyz="0.00000 0.00000 0.00000"/>
            <mass value="0.000000001"/>
            <inertia ixx="0.0" ixy="0" ixz="0" iyy="0.0" iyz="0" izz="0.0"/>
        </inertial>
        <visual>
            <origin rpy="0 0 0.0" xyz="0 0 0"/>
            <geometry>
                <mesh filename="meshes/hand/body3.obj" scale="1 1 1"/>
            </geometry>
        </visual>
    </link>

    <joint name="link_0_3" type="revolute">
        <parent link="link0"/>
        <child link="link3"/>
        <origin xyz="4.689700 -4.425000 0.000000"/>   
        <axis xyz="0.000000 0.000000 -1.000000"/>
    </joint>

    <link name="link4">
        <inertial>
            <origin rpy="0.00000 -0.00000 0.00000" xyz="0.00000 0.00000 0.00000"/>
            <mass value="0.000000001"/>
            <inertia ixx="0.0" ixy="0" ixz="0" iyy="0.0" iyz="0" izz="0.0"/>
        </inertial>
        <visual>
            <origin rpy="0 0 0.0" xyz="0 0 0"/>
            <geometry>
                <mesh filename="meshes/hand/body4.obj" scale="1 1 1"/>
            </geometry>
        </visual>
    </link>

     <joint name="link_3_4" type="revolute">
        <parent link="link3"/>
        <child link="link4"/>
        <origin xyz="6.680000 -4.425000 0.000000"/>   
        <axis xyz="1.000000 0.000000 0.000000"/>
    </joint>


    <link name="link5">
        <inertial>
            <origin rpy="0.00000 -0.00000 0.00000" xyz="0.00000 0.00000 0.00000"/>
            <mass value="0.000000001"/>
            <inertia ixx="0.0" ixy="0" ixz="0" iyy="0.0" iyz="0" izz="0.0"/>
        </inertial>
        <visual>
            <origin rpy="0 0 0.0" xyz="0 0 0"/>
            <geometry>
                <mesh filename="meshes/hand/body5.obj" scale="1 1 1"/>
            </geometry>
        </visual>
    </link>

    <joint name="link_4_5" type="revolute">
        <parent link="link4"/>
        <child link="link5"/>
        <origin xyz="11.080000 -4.425000 0.000000"/>   
        <axis xyz="1.000000 0.000000 0.000000"/>
    </joint>

    <link name="link6">
        <inertial>
            <origin rpy="0.00000 -0.00000 0.00000" xyz="0.00000 0.00000 0.00000"/>
            <mass value="0.000000001"/>
            <inertia ixx="0.0" ixy="0" ixz="0" iyy="0.0" iyz="0" izz="0.0"/>
        </inertial>
        <visual>
            <origin rpy="0 0 0.0" xyz="0 0 0"/>
            <geometry>
                <mesh filename="meshes/hand/body6.obj" scale="1 1 1"/>
            </geometry>
        </visual>
    </link>

    <joint name="link_5_6" type="revolute">
        <parent link="link5"/>
        <child link="link6"/>
        <origin xyz="15.480000 -4.425000 0.000000"/>   
        <axis xyz="1.000000 0.000000 0.000000"/>
    </joint>


    <link name="link7">
        <inertial>
            <origin rpy="0.00000 -0.00000 0.00000" xyz="0.00000 0.00000 0.00000"/>
            <mass value="0.000000001"/>
            <inertia ixx="0.0" ixy="0" ixz="0" iyy="0.0" iyz="0" izz="0.0"/>
        </inertial>
        <visual>
            <origin rpy="0 0 0.0" xyz="0 0 0"/>
            <geometry>
                <mesh filename="meshes/hand/body7.obj" scale="1 1 1"/>
            </geometry>
        </visual>
    </link>


    <joint name="link_0_7" type="revolute">
        <parent link="link0"/>
        <child link="link7"/>
        <origin xyz="4.689700 -1.475000 0.000000"/>   
        <axis xyz="0.000000 0.000000 -1.000000"/>
    </joint>

    <link name="link8">
        <inertial>
            <origin rpy="0.00000 -0.00000 0.00000" xyz="0.00000 0.00000 0.00000"/>
            <mass value="0.000000001"/>
            <inertia ixx="0.0" ixy="0" ixz="0" iyy="0.0" iyz="0" izz="0.0"/>
        </inertial>
        <visual>
            <origin rpy="0 0 0.0" xyz="0 0 0"/>
            <geometry>
                <mesh filename="meshes/hand/body8.obj" scale="1 1 1"/>
            </geometry>
        </visual>
    </link>



    <joint name="link_7_8" type="revolute">
        <parent link="link7"/>
        <child link="link8"/>
        <origin xyz="6.680000 -1.475000 0.000000"/>   
        <axis xyz="1.000000 0.000000 0.000000"/>
    </joint>

    <link name="link9">
        <inertial>
            <origin rpy="0.00000 -0.00000 0.00000" xyz="0.00000 0.00000 0.00000"/>
            <mass value="0.000000001"/>
            <inertia ixx="0.0" ixy="0" ixz="0" iyy="0.0" iyz="0" izz="0.0"/>
        </inertial>
        <visual>
            <origin rpy="0 0 0.0" xyz="0 0 0"/>
            <geometry>
                <mesh filename="meshes/hand/body9.obj" scale="1 1 1"/>
            </geometry>
        </visual>
    </link>

    <joint name="link_8_9" type="revolute">
        <parent link="link8"/>
        <child link="link9"/>
        <origin xyz="11.080000 -1.475000 0.000000"/>   
        <axis xyz="1.000000 0.000000 0.000000"/>
    </joint>

    <link name="link10">
        <inertial>
            <origin rpy="0.00000 -0.00000 0.00000" xyz="0.00000 0.00000 -0.00000"/>
            <mass value="0.000000001"/>
            <inertia ixx="0.000000001" ixy="0" ixz="0" iyy="0.000000001" iyz="0" izz="0.000000001"/>
        </inertial>
        <visual>
            <origin rpy="0 0 0.0" xyz="0.000000 0.000000 0.000000"/>
            <geometry>
                <mesh filename="meshes/hand/body10.obj" scale="1 1 1"/>
            </geometry>
        </visual>
    </link>

    <joint name="link_9_10" type="revolute">
        <parent link="link9"/>
        <child link="link10"/>
        <origin xyz="15.480000 -1.475000 0.000000"/>
        <axis xyz="1.000000 0.000000 0.000000"/>
    </joint>


    <link name="link11">
        <inertial>
            <origin rpy="0.00000 -0.00000 0.00000" xyz="0.000000 0.000000 0.000000"/>
            <mass value="0.000000001"/>
            <inertia ixx="0.000000001" ixy="0" ixz="0" iyy="0.000000001" iyz="0" izz="0.000000001"/>
        </inertial>
        <visual>
            <origin rpy="0 0 0.0" xyz="0.000000 0.000000 0.000000"/>
            <geometry>
                <mesh filename="meshes/hand/body11.obj" scale="1 1 1"/>
            </geometry>
        </visual>
    </link>

    <joint name="link_0_11" type="revolute">
        <parent link="link0"/>
        <child link="link11"/>
        <origin xyz="4.689700 1.475000 0.000000"/>
        <axis xyz="0.000000 0.000000 -1.000000"/>
    </joint>

    <link name="link12">
        <inertial>
            <origin rpy="0.00000 -0.00000 0.00000" xyz="0.000000 0.000000 0.000000"/>
            <mass value="0.000000001"/>
            <inertia ixx="0.000000001" ixy="0" ixz="0" iyy="0.000000001" iyz="0" izz="0.000000001"/>
        </inertial>
        <visual>
            <origin rpy="0 0 0.0" xyz="0.000000 0.000000 0.000000"/>
            <geometry>
                <mesh filename="meshes/hand/body12.obj" scale="1 1 1"/>
            </geometry>
        </visual>
    </link>

    <joint name="link_11_12" type="revolute">
        <parent link="link11"/>
        <child link="link12"/>
        <origin xyz="6.680000 1.475000 0.000000"/>
        <axis xyz="1.000000 0.000000 0.000000"/>
    </joint>

    <link name="link13">
        <inertial>
            <origin rpy="0.00000 -0.00000 0.00000" xyz="0.000000 0.000000 0.000000"/>
            <mass value="0.000000001"/>
            <inertia ixx="0.000000001" ixy="0" ixz="0" iyy="0.000000001" iyz="0" izz="0.000000001"/>
        </inertial>
        <visual>
            <origin rpy="0 0 0.0" xyz="0.000000 0.000000 0.000000"/>
            <geometry>
                <mesh filename="meshes/hand/body13.obj" scale="1 1 1"/>
            </geometry>
        </visual>
    </link>

    <joint name="link_12_13" type="revolute">
        <parent link="link12"/>
        <child link="link13"/>
        <origin xyz="11.080000 1.475000 0.000000"/>
        <axis xyz="1.000000 0.000000 0.000000"/>
    </joint>

    <link name="link14">
        <inertial>
            <origin rpy="0.00000 -0.00000 0.00000" xyz="0.000000 0.000000 0.000000"/>
            <mass value="0.000000001"/>
            <inertia ixx="0.000000001" ixy="0" ixz="0" iyy="0.000000001" iyz="0" izz="0.000000001"/>
        </inertial>
        <visual>
            <origin rpy="0 0 0.0" xyz="0.000000 0.000000 0.000000"/>
            <geometry>
                <mesh filename="meshes/hand/body14.obj" scale="1 1 1"/>
            </geometry>
        </visual>
    </link>

    <joint name="link_13_14" type="revolute">
        <parent link="link13"/>
        <child link="link14"/>
        <origin xyz="15.480000 1.475000 0.000000"/>
        <axis xyz="1.000000 0.000000 0.000000"/>
    </joint>


    <link name="link15">
        <inertial>
            <origin rpy="0.00000 -0.00000 0.00000" xyz="0.000000 0.000000 0.000000"/>
            <mass value="0.000000001"/>
            <inertia ixx="0.000000001" ixy="0" ixz="0" iyy="0.000000001" iyz="0" izz="0.000000001"/>
        </inertial>
        <visual>
            <origin rpy="0 0 0.0" xyz="0.000000 0.000000 0.000000"/>
            <geometry>
                <mesh filename="meshes/hand/body15.obj" scale="1 1 1"/>
            </geometry>
        </visual>
    </link>

    <joint name="link_0_15" type="revolute">
        <parent link="link0"/>
        <child link="link15"/>
        <origin xyz="4.689700 4.425000 0.000000"/>
        <axis xyz="0.000000 0.000000 -1.000000"/>
    </joint>

    <link name="link16">
        <inertial>
            <origin rpy="0.00000 -0.00000 0.00000" xyz="0.000000 0.000000 -0.000000"/>
            <mass value="0.000000001"/>
            <inertia ixx="0.000000001" ixy="0" ixz="0" iyy="0.000000001" iyz="0" izz="0.000000001"/>
        </inertial>
        <visual>
            <origin rpy="0 0 0.0" xyz="0.000000 0.000000 0.000000"/>
            <geometry>
                <mesh filename="meshes/hand/body16.obj" scale="1 1 1"/>
            </geometry>
        </visual>

    </link>

    <joint name="link_15_16" type="revolute">
        <parent link="link15"/>
        <child link="link16"/>
        <origin xyz="6.680000 4.425000 0.000000"/>
        <axis xyz="1.000000 0.000000 0.000000"/>
    </joint>

    <link name="link17">
        <inertial>
            <origin rpy="0.00000 -0.00000 0.00000" xyz="0.000000 0.000000 -0.000000"/>
            <mass value="0.000000001"/>
            <inertia ixx="0.000000001" ixy="0" ixz="0" iyy="0.000000001" iyz="0" izz="0.000000001"/>
        </inertial>
        <visual>
            <origin rpy="0 0 0.0" xyz="0.000000 0.000000 0.000000"/>
            <geometry>
                <mesh filename="meshes/hand/body17.obj" scale="1 1 1"/>
            </geometry>
        </visual>
    </link>

    <joint name="link_16_17" type="revolute">
        <parent link="link16"/>
        <child link="link17"/>
        <origin xyz="11.080000 4.425000 0.000000"/>
        <axis xyz="1.000000 0.000000 0.000000"/>
    </joint>


</robot>

